<?xml version="1.0"?>
<robot name="simple_robot">
	<link name="base_link">
		<visual>
			<geometry>
				<cylinder length="0.05" radius="0.2"/>
			</geometry>
			<!--origin of the reference frame of the visual element with respect to the reference frame of the link -->
			<!-- rpy - r is roll, p is pitch, y is yaw -->
			<!-- xzy - x, y, z are offsets -->
			<origin rpy = "0 0 0" xyz = "0 0 0" />
			<material name = "yellow">
				<color rgba = "1 1 0 1" />
			</material>
		</visual>
	</link>
	
	<joint name="joint_1" type="revolute">
		<parent link="base_link"/>
		<child link="first_link"/>
		<origin xyz="0 0 0.025"/>
		<axis xyz="0 0 1"/>
		<limit effort="300" velocity="2.0" lower="-2.2" upper="2.2" />
	</joint>
	<link name="first_link">
		<visual>
			<geometry>
				<cylinder length="0.5" radius="0.04"/>
			</geometry>
			<origin rpy="0 0 0" xyz="0 0 0.25"/>
			<material name="blue">
				<color rgba="0 0 1 1"/>
			</material>
		</visual>
	</link>
	
	<joint name="joint_2" type="revolute">
		<parent link="first_link"/>
		<child link="second_link"/>
		<origin xyz="0 0 0.5" rpy="1.57079633 0 0"/>
		<axis xyz="0 0 1"/>
		<limit effort="300" velocity="2.0" lower="-2.2" upper="2.2" />
	</joint>
	
	<link name="second_link">
		<visual>
			<geometry>
				<box size="0.5 0.1 0.1"/>
			</geometry>
			<origin rpy="0 0 0" xyz="0.25 0 0"/>
			<material name="green">
				<color rgba="0 1 0 1"/>
			</material>
		</visual>
	</link>
	
	<joint name="joint_3" type="revolute">
		<parent link="second_link"/>
		<child link="third_link"/>
		<origin xyz="0.5 0 0"/>
		<axis xyz="0 0 1"/>
		<limit effort="300" velocity="2.0" lower="-2.2" upper="2.2" />
	</joint>
	<link name="third_link">
		<visual>
			<geometry>
				<box size="0.5 0.1 0.1"/>
			</geometry>
			<origin rpy="0 0 0" xyz="0.25 0 0"/>
			<material name="yellow">
				<color rgba="1 1 0 1"/>
			</material>
		</visual>
	</link>
	
		<joint name="joint_4" type="revolute">
		<parent link="third_link"/>
		<child link="fourth_link"/>
		<origin xyz="0.5 0 0"/>
		<axis xyz="0 1 0"/>
		<limit effort="300" velocity="2.0" lower="-1.2" upper="1" />
	</joint>
	<link name="fourth_link">
		<visual>
			<geometry>
				<box size="0.15 0.08 0.08"/>
			</geometry>
			<origin rpy="0 0 0" xyz="0.075 0 0"/>
			<material name="yellow">
				<color rgba="1 1 0 1"/>
			</material>
		</visual>
	</link>
	
	<joint name="joint_5" type="revolute">
		<parent link="fourth_link"/>
		<child link="fifth_link"/>
		<origin xyz="0.15 0 0"/>
		<axis xyz="1 0 0"/>
		<limit effort="300" velocity="2.0" lower="-1.2" upper="1" />
	</joint>
	<link name="fifth_link">
		<visual>
			<geometry>
				<box size="0.15 0.08 0.08"/>
			</geometry>
			<origin rpy="0 0 0" xyz="0.075 0 0"/>
			<material name="yellow">
				<color rgba="1 1 0 1"/>
			</material>
		</visual>
	</link>
</robot>
